Workbook
Name censusdays: #REF!
Name circ: #REF!
Name IQ_CH: 110000
Name IQ_CQ: 5000
Name IQ_CY: 10000
Name IQ_DAILY: 500000
Name IQ_FH: 100000
Name IQ_FQ: 500
Name IQ_FY: 1000
Name IQ_LTM: 2000
Name IQ_MONTH: 15000
Name IQ_NTM: 6000
Name IQ_WEEK: 50000
Name IQ_YTD: 3000
Name mil: #REF!
Name QuickView_QuickView1: #REF!
Name QuickView_QuickView1_ColHeader: #REF!
Name QuickView_QuickView1_Data: #REF!
Name QuickView_QuickView1_RowHeader: #REF!
Name QuickView_QuickView1_UpperLeft: #REF!
Name QuickView_QuickView2: #REF!
Name QuickView_QuickView2_ColHeader: #REF!
Name QuickView_QuickView2_Data: #REF!
Name QuickView_QuickView2_RowHeader: #REF!
Name QuickView_QuickView2_UpperLeft: #REF!
Name QuickView_QuickView3: #REF!
Name QuickView_QuickView3_ColHeader: #REF!
Name QuickView_QuickView3_Data: #REF!
Name QuickView_QuickView3_RowHeader: #REF!
Name QuickView_QuickView3_UpperLeft: #REF!
Name QuickView_QuickView4: #REF!
Name QuickView_QuickView4_ColHeader: #REF!
Name QuickView_QuickView4_Data: #REF!
Name QuickView_QuickView4_RowHeader: #REF!
Name QuickView_QuickView4_UpperLeft: #REF!
Name QuickView_QuickView5: #REF!
Name QuickView_QuickView5_ColHeader: #REF!
Name QuickView_QuickView5_Data: #REF!
Name QuickView_QuickView5_RowHeader: #REF!
Name QuickView_QuickView5_UpperLeft: #REF!
Name QuickView_QuickView6: #REF!
Name QuickView_QuickView6_ColHeader: #REF!
Name QuickView_QuickView6_Data: #REF!
Name QuickView_QuickView6_RowHeader: #REF!
Name QuickView_QuickView6_UpperLeft: #REF!
Name QuickView_QuickView7: #REF!
Name QuickView_QuickView7_ColHeader: #REF!
Name QuickView_QuickView7_Data: #REF!
Name QuickView_QuickView7_RowHeader: #REF!
Name QuickView_QuickView7_UpperLeft: #REF!
Name QuickView_QuickView8: #REF!
Name QuickView_QuickView8_ColHeader: #REF!
Name QuickView_QuickView8_Data: #REF!
Name QuickView_QuickView8_RowHeader: #REF!
Name QuickView_QuickView8_UpperLeft: #REF!

Sheet Revenue Waterfall
B3: Budget | C3: =Facility!F78 -> 5703208.5
B4: Vol - Mcare | C4: =Facility!J80 -> 17659.644
B5: Vol - Mcaid | C5: =Facility!J81 -> -554992.75
B6: Vol - Comm | C6: =Facility!J82 -> -134793.8
B7: Vol - Other Gov't | C7: =Facility!J83 -> -306.98424
B8: Vol - Self Pay | C8: =Facility!J84 -> 4065.1012
B9: Rate - Mcare | C9: =Facility!O80 -> 170542.22
B10: Rate - Mcaid | C10: =Facility!O81 -> 2286509.6
B11: Rate - Comm | C11: =Facility!O82 -> -170995.82
B12: Rate - Other Gov't | C12: =Facility!O83 -> -4262.51
B13: Rate - Self Pay | C13: =Facility!O84 -> 194416.58
B14: Actual | C14: =SUM(C3:C13) -> 7511049.9
C15: =C14=Facility!E78 -> FALSE | D15: =+MOR_MTD!B44 -> 5911901.3 | E15: =+D15-C14 -> -1599148.6

Sheet EBITDA Waterfall
B3: Budget | C3: =ROUND(+Facility!F215,2) -> 2862385
B4: Net Rev - Vol | C4: =ROUND(+Facility!O77,2) -> 0
B5: Net Rev - Rate | C5: =ROUND(+Facility!O78,2) -> 2476210.1
B6: Labor - FTE | C6: =ROUND(+Facility!O129,2) -> 1.36
B7: Labor - FTE Rate | C7: =ROUND(+Facility!O130,2) -> 0
B8: Supplies - Vol | C8: =ROUND(+Facility!O169,2) -> 6388.29
B9: Supplies - Rate | C9: =ROUND(+Facility!O170,2) -> 2917.37
B10: Purch Svc | C10: =ROUND(+Facility!O180,2) -> -12349.92
B11: Pro Fee | C11: =ROUND(+Facility!O189,2) -> 7450.11
B12: Other Non-Labor Opex | C12: =ROUND(+Facility!O201,2) -> 14928.94
B13: Actual | C13: =+SUM(C3:C12) -> 5357931.2
C14: =C13=Facility!E215 -> FALSE

Sheet MOR_MTD
A1: MTD | B1: =+Facility!B6 -> Acute_DIV1 - Highland Hospital
B3: Actual | C3: Budget | D3: Var | E3: Var % | G3: PM | H3: Var | I3: Var % | K3: PYSM | L3: Var | M3: Var %
A5: Admissions | B5: =+Facility!E8 -> 245 | C5: =+Facility!F8 -> 284.21713 | D5: =+B5-C5 -> -39.217131 | E5: =+IF(D5=0,0,D5/C5) -> -0.13798299 | G5: =+Facility!N8 -> 259 | H5: =B5-G5 -> -14 | I5: =+IF(H5=0,0,IF(AND(G5=0,H5>0),-100%,H5/G5)) -> -0.054054054 | K5: =+Facility!AE8 -> 237 | L5: =+B5-K5 -> 8 | M5: =+IF(L5=0,0,IF(AND(K5=0,L5>0),-100%,L5/K5)) -> 0.033755274
A7: Payor Mix (admits)
A8: Medicare | B8: =+Facility!E10/Facility!E$8 -> 0.06122449 | C8: =+Facility!F10/Facility!F$8 -> 0.11019255 | D8: =+B8-C8 -> -0.048968063 | G8: =+Facility!N10/Facility!N$8 -> 0.057915058 | H8: =B8-G8 -> 0.0033094319 | K8: =+Facility!AE10/Facility!AE$8 -> 0.10548523 | L8: =+B8-K8 -> -0.044260742
A9: Medicaid | B9: =+Facility!E11/Facility!E$8 -> 0.70612245 | C9: =+Facility!F11/Facility!F$8 -> 0.59106685 | D9: =+B9-C9 -> 0.1150556 | G9: =+Facility!N11/Facility!N$8 -> 0.73745174 | H9: =B9-G9 -> -0.031329288 | K9: =+Facility!AE11/Facility!AE$8 -> 0.67932489 | L9: =+B9-K9 -> 0.026797554
A10: Commercial | B10: =+Facility!E12/Facility!E$8 -> 0.2 | C10: =+Facility!F12/Facility!F$8 -> 0.27079587 | D10: =+B10-C10 -> -0.070795865 | G10: =+Facility!N12/Facility!N$8 -> 0.19305019 | H10: =B10-G10 -> 0.0069498069 | K10: =+Facility!AE12/Facility!AE$8 -> 0.18565401 | L10: =+B10-K10 -> 0.014345992
A11: Other Government | B11: =+Facility!E13/Facility!E$8 -> 0.012244898 | C11: =+Facility!F13/Facility!F$8 -> 0.0061978617 | D11: =+B11-C11 -> 0.0060470363 | G11: =+Facility!N13/Facility!N$8 -> 0.0077220077 | H11: =B11-G11 -> 0.0045228902 | K11: =+Facility!AE13/Facility!AE$8 -> 0.0084388186 | L11: =+B11-K11 -> 0.0038060794
A12: Self Pay | B12: =+Facility!E14/Facility!E$8 -> 0.020408163 | C12: =+Facility!F14/Facility!F$8 -> 0.021746871 | D12: =+B12-C12 -> -0.0013387079 | G12: =+Facility!N14/Facility!N$8 -> 0.0038610039 | H12: =B12-G12 -> 0.016547159 | K12: =+Facility!AE14/Facility!AE$8 -> 0.021097046 | L12: =+B12-K12 -> -0.00068888315
A14: Inpatient Days | B14: =+Facility!E29 -> 2555 | C14: =+Facility!F29 -> 2856 | D14: =+B14-C14 -> -301 | E14: =+IF(D14=0,0,D14/C14) -> -0.10539216 | G14: =+Facility!N29 -> 2810 | H14: =B14-G14 -> -255 | I14: =+IF(H14=0,0,IF(AND(G14=0,H14>0),-100%,H14/G14)) -> -0.090747331 | K14: =+Facility!AE29 -> 3389 | L14: =+B14-K14 -> -834 | M14: =+IF(L14=0,0,IF(AND(K14=0,L14>0),-100%,L14/K14)) -> -0.24609029
A15: LOS | B15: =+Facility!E32 -> 10.4 | C15: =+Facility!F32 -> 10 | D15: =+B15-C15 -> 0.4 | E15: =+IF(D15=0,0,D15/C15) -> 0.04 | G15: =+Facility!N32 -> 10.849421 | H15: =B15-G15 -> -0.44942085 | I15: =+IF(H15=0,0,IF(AND(G15=0,H15>0),-100%,H15/G15)) -> -0.041423488 | K15: =+Facility!AE32 -> 14.299578 | L15: =+B15-K15 -> -3.8995781 | M15: =+IF(L15=0,0,IF(AND(K15=0,L15>0),-100%,L15/K15)) -> -0.27270581
A16: ADC | B16: =+Facility!E33 -> 85.166667 | C16: =+Facility!F33 -> 95.2 | D16: =+B16-C16 -> -10.033333 | E16: =+IF(D16=0,0,D16/C16) -> -0.10539216 | G16: =+Facility!N33 -> 90.645161 | H16: =B16-G16 -> -5.4784946 | I16: =+IF(H16=0,0,IF(AND(G16=0,H16>0),-100%,H16/G16)) -> -0.060438909 | K16: =+Facility!AE33 -> 112.96667 | L16: =+B16-K16 -> -27.8 | M16: =+IF(L16=0,0,IF(AND(K16=0,L16>0),-100%,L16/K16)) -> -0.24609029
A17: Occupancy | B17: =+Facility!E31 -> 1.3736559 | C17: =+Facility!F31 -> 1.5354839 | D17: =+B17-C17 -> -0.16182796 | G17: =+Facility!N31 -> 0.65684899 | H17: =B17-G17 -> 0.71680692 | K17: =+Facility!AE31 -> 0.81859903 | L17: =+B17-K17 -> 0.55505688
A18: Equivalent ADC | B18: =Facility!E34 -> 84.117104 | C18: =Facility!F34 -> 97.08282 | D18: =+B18-C18 -> -12.965716 | E18: =+IF(D18=0,0,D18/C18) -> -0.13355314 | G18: =Facility!N34 -> 93.513273 | H18: =B18-G18 -> -9.3961688 | I18: =+IF(H18=0,0,IF(AND(G18=0,H18>0),-100%,H18/G18)) -> -0.10047952 | K18: =Facility!AE34 -> 117.22815 | L18: =+B18-K18 -> -33.111045 | M18: =+IF(L18=0,0,IF(AND(K18=0,L18>0),-100%,L18/K18)) -> -0.28244961
A20: Service Mix (ADC)
A21: Children | B21: =Facility!E55/Facility!E$33 -> 0 | C21: =Facility!F55/Facility!F$33 -> 0 | D21: =+B21-C21 -> 0 | K21: =Facility!AE55/Facility!AE$33 -> 0 | L21: =+B21-K21 -> 0
A22: Pre-Adolescent | B22: =Facility!E56/Facility!E$33 -> 0 | C22: =Facility!F56/Facility!F$33 -> 0 | D22: =+B22-C22 -> 0 | K22: =Facility!AE56/Facility!AE$33 -> 0 | L22: =+B22-K22 -> 0
A23: Adolescent | B23: =Facility!E57/Facility!E$33 -> 0.39960861 | C23: =Facility!F57/Facility!F$33 -> 0.40091036 | D23: =+B23-C23 -> -0.0013017536 | G23: =Facility!N57/Facility!N$33 -> 0.38540925 | H23: =B23-G23 -> 0.014199358 | K23: =Facility!AE57/Facility!AE$33 -> 0.31071112 | L23: =+B23-K23 -> 0.088897486
A24: Adult | B24: =Facility!E58/Facility!E$33 -> 0.56086106 | C24: =Facility!F58/Facility!F$33 -> 0.54831933 | D24: =+B24-C24 -> 0.012541729 | G24: =Facility!N58/Facility!N$33 -> 0.56939502 | H24: =B24-G24 -> -0.008533961 | K24: =Facility!AE58/Facility!AE$33 -> 0.45441133 | L24: =+B24-K24 -> 0.10644973
A25: Chem Dep | B25: =Facility!E59/Facility!E$33 -> 0 | C25: =Facility!F59/Facility!F$33 -> 0 | D25: =+B25-C25 -> 0 | H25: =B25-G25 -> 0 | K25: =Facility!AE59/Facility!AE$33 -> 0 | L25: =+B25-K25 -> 0
A26: Gero | B26: 0 | C26: =Facility!F60/Facility!F$33 -> 0 | D26: =+B26-C26 -> 0 | H26: =B26-G26 -> 0 | K26: 0 | L26: =+B26-K26 -> 0
A27: PRTF | B27: =Facility!E61/Facility!E$33 -> 0 | C27: =Facility!F61/Facility!F$33 -> 0 | D27: =+B27-C27 -> 0 | H27: =B27-G27 -> 0 | K27: =Facility!AE61/Facility!AE$33 -> 0.19563293 | L27: =+B27-K27 -> -0.19563293
A28: Detox | B28: =Facility!E62/Facility!E$33 -> 0.039530333 | C28: =Facility!F62/Facility!F$33 -> 0.050770308 | D28: =+B28-C28 -> -0.011239975 | G28: =Facility!N62/Facility!N$33 -> 0.04519573 | H28: =B28-G28 -> -0.0056653969 | K28: =Facility!AE62/Facility!AE$33 -> 0.039244615 | L28: =+B28-K28 -> 0.00028571775
A29: RTC | B29: =Facility!E63/Facility!E$33 -> 0 | C29: =Facility!F63/Facility!F$33 -> 0 | D29: =+B29-C29 -> 0 | K29: =Facility!AE63/Facility!AE$33 -> 0 | L29: =+B29-K29 -> 0
A30: PHP with Boarding | B30: =Facility!E64/Facility!E$33 -> 0 | C30: =Facility!F64/Facility!F$33 -> 0 | D30: =+B30-C30 -> 0 | K30: =Facility!AE64/Facility!AE$33 -> 0 | L30: =+B30-K30 -> 0
A31: IOP with Boarding | B31: =Facility!E65/Facility!E$33 -> 0 | C31: =Facility!F65/Facility!F$33 -> 0 | D31: =+B31-C31 -> 0 | K31: =Facility!AE65/Facility!AE$33 -> 0 | L31: =+B31-K31 -> 0
A33: Outpatient Visits | B33: =+Facility!E68 -> 0 | C33: =+Facility!F68 -> 0 | D33: =+B33-C33 -> 0 | E33: =+IF(D33=0,0,D33/C33) -> 0 | K33: =+Facility!AE68 -> 0 | L33: =+B33-K33 -> 0 | M33: =+IF(L33=0,0,IF(AND(K33=0,L33>0),-100%,L33/K33)) -> 0
A35: Service Mix (visits)
A36: PHP | B36: =IF(Facility!E70=0,0,Facility!E70/Facility!E$68) -> 0 | C36: =IF(Facility!F70=0,0,Facility!F70/Facility!F$68) -> 0 | D36: =+B36-C36 -> 0 | G36: =IF(Facility!N70=0,0,Facility!N70/Facility!N$68) -> 0 | H36: =B36-G36 -> 0 | K36: =IF(Facility!AE70=0,0,Facility!AE70/Facility!AE$68) -> 0 | L36: =+B36-K36 -> 0
A37: IOP | B37: =IF(Facility!E71=0,0,Facility!E71/Facility!E$68) -> 0 | C37: =IF(Facility!F71=0,0,Facility!F71/Facility!F$68) -> 0 | D37: =+B37-C37 -> 0 | G37: =IF(Facility!N71=0,0,Facility!N71/Facility!N$68) -> 0 | H37: =B37-G37 -> 0 | K37: =IF(Facility!AE71=0,0,Facility!AE71/Facility!AE$68) -> 0 | L37: =+B37-K37 -> 0
A38: Traditional | B38: =IF(Facility!E72=0,0,Facility!E72/Facility!E$68) -> 0 | C38: =IF(Facility!F72=0,0,Facility!F72/Facility!F$68) -> 0 | D38: =+B38-C38 -> 0 | G38: =IF(Facility!N72=0,0,Facility!N72/Facility!N$68) -> 0 | H38: =B38-G38 -> 0 | K38: =IF(Facility!AE72=0,0,Facility!AE72/Facility!AE$68) -> 0 | L38: =+B38-K38 -> 0
A39: ECT/SLE | B39: =IF(Facility!E73=0,0,Facility!E73/Facility!E$68) -> 0 | C39: =IF(Facility!F73=0,0,Facility!F73/Facility!F$68) -> 0 | D39: =+B39-C39 -> 0 | G39: =IF(Facility!N73=0,0,Facility!N73/Facility!N$68) -> 0 | H39: =B39-G39 -> 0 | K39: =IF(Facility!AE73=0,0,Facility!AE73/Facility!AE$68) -> 0 | L39: =+B39-K39 -> 0
B42: Actual | C42: Budget | D42: Var | E42: Var % | K42: PYSM | L42: Var | M42: Var %
B43: Actual | C43: Budget | D43: Var | E43: Var % | G43: PM | H43: Var | I43: Var % | K43: PYSM | L43: Var | M43: Var %
A44: Net Revenue | B44: =+Facility!E78 -> 5911901.3 | C44: =+Facility!F78 -> 5703208.5 | D44: =+B44-C44 -> 208692.77 | E44: =+IF(D44=0,0,D44/C44) -> 0.036592169 | G44: =+Facility!N78 -> 3435691.2 | H44: =B44-G44 -> 2476210.1 | I44: =+IF(H44=0,0,IF(AND(G44=0,H44>0),-100%,H44/G44)) -> 0.72073129 | K44: =+Facility!AE78 -> 3755568.4 | L44: =+B44-K44 -> 2156332.9 | M44: =+IF(L44=0,0,IF(AND(K44=0,L44>0),-100%,L44/K44)) -> 0.57416953
A45: Inpatient | B45: =Facility!E87 -> 5952867.6 | C45: =Facility!F87 -> 5588382.7 | D45: =+B45-C45 -> 364484.92 | E45: =+IF(D45=0,0,D45/C45) -> 0.065221898 | G45: =Facility!N87 -> 3333340.3 | H45: =B45-G45 -> 2619527.3 | I45: =+IF(H45=0,0,IF(AND(G45=0,H45>0),-100%,H45/G45)) -> 0.78585654 | K45: =Facility!AE87 -> 3617667.7 | L45: =+B45-K45 -> 2335199.9 | M45: =+IF(L45=0,0,IF(AND(K45=0,L45>0),-100%,L45/K45)) -> 0.64549871
A46: Outpatient | B46: =Facility!E88 -> 0 | C46: =Facility!F88 -> 0 | D46: =+B46-C46 -> 0 | E46: =+IF(D46=0,0,D46/C46) -> 0 | G46: =Facility!N88 -> 0 | H46: =B46-G46 -> 0 | I46: =+IF(H46=0,0,IF(AND(G46=0,H46>0),-100%,H46/G46)) -> 0 | K46: =Facility!AE88 -> 0 | L46: =+B46-K46 -> 0 | M46: =+IF(L46=0,0,IF(AND(K46=0,L46>0),-100%,L46/K46)) -> 0
A47: Professional Fee | B47: =Facility!E89 -> 128305.05 | C47: =Facility!F89 -> 110014.62 | D47: =+B47-C47 -> 18290.432 | E47: =+IF(D47=0,0,D47/C47) -> 0.16625456 | G47: =Facility!N89 -> 79238 | H47: =B47-G47 -> 49067.05 | I47: =+IF(H47=0,0,IF(AND(G47=0,H47>0),-100%,H47/G47)) -> 0.61923635 | K47: =Facility!AE89 -> 137248.39 | L47: =+B47-K47 -> -8943.34 | M47: =+IF(L47=0,0,IF(AND(K47=0,L47>0),-100%,L47/K47)) -> -0.065161712
A49: IP Net PPD | B49: =Facility!E87/Facility!E29 -> 2329.8895 | C49: =Facility!F87/Facility!F29 -> 1956.7166 | D49: =+B49-C49 -> 373.17285 | E49: =+IF(D49=0,0,D49/C49) -> 0.19071379 | G49: =Facility!N87/Facility!N29 -> 1186.2421 | H49: =B49-G49 -> 1143.6474 | I49: =+IF(H49=0,0,IF(AND(G49=0,H49>0),-100%,H49/G49)) -> 0.96409271 | K49: =Facility!AE87/Facility!AE29 -> 1067.4735 | L49: =+B49-K49 -> 1262.416 | M49: =+IF(L49=0,0,IF(AND(K49=0,L49>0),-100%,L49/K49)) -> 1.1826204
A50: OP Net POPV | B50: =IF(Facility!E68=0,0,Facility!E88/Facility!E68) -> 0 | C50: =IF(Facility!F68=0,0,Facility!F88/Facility!F68) -> 0 | D50: =+B50-C50 -> 0 | E50: =+IF(D50=0,0,D50/C50) -> 0 | G50: =IF(Facility!N68=0,0,Facility!N88/Facility!N68) -> 0 | I50: =+IF(H50=0,0,IF(AND(G50=0,H50>0),-100%,H50/G50)) -> 0 | K50: =IF(Facility!AE68=0,0,Facility!AE88/Facility!AE68) -> 0 | L50: =+B50-K50 -> 0 | M50: =+IF(L50=0,0,IF(AND(K50=0,L50>0),-100%,L50/K50)) -> 0
...

Sheet MOR_YTD
A1: YTD | B1: =+Facility!B6 -> Acute_DIV1 - Highland Hospital
B3: Actual | C3: Budget | D3: Var | E3: Var % | G3: PYTD | H3: Var | I3: Var %
A5: Admissions | B5: =Facility!V8 -> 997 | C5: =Facility!W8 -> 1109.0408 | D5: =+B5-C5 -> -112.04076 | E5: =+IF(D5=0,0,D5/C5) -> -0.10102492 | G5: =+Facility!AM8 -> 858 | H5: =+B5-G5 -> 139 | I5: =+IF(H5=0,0,IF(AND(G5=0,H5>0),-100%,H5/G5)) -> 0.16200466
A7: Payor Mix (admits)
A8: Medicare | B8: =+Facility!V10/Facility!V$8 -> 0.059177533 | C8: =+Facility!W10/Facility!W$8 -> 0.12302902 | D8: =+B8-C8 -> -0.063851485 | G8: =+Facility!AM10/Facility!AM$8 -> 0.094405594 | H8: =+B8-G8 -> -0.035228062
A9: Medicaid | B9: =+Facility!V11/Facility!V$8 -> 0.74322969 | C9: =+Facility!W11/Facility!W$8 -> 0.6504191 | D9: =+B9-C9 -> 0.092810587 | G9: =+Facility!AM11/Facility!AM$8 -> 0.68414918 | H9: =+B9-G9 -> 0.059080505
A10: Commercial | B10: =+Facility!V12/Facility!V$8 -> 0.17352056 | C10: =+Facility!W12/Facility!W$8 -> 0.21254438 | D10: =+B10-C10 -> -0.039023823 | G10: =+Facility!AM12/Facility!AM$8 -> 0.2016317 | H10: =+B10-G10 -> -0.02811114
A11: Other Government | B11: =+Facility!V13/Facility!V$8 -> 0.01003009 | C11: =+Facility!W13/Facility!W$8 -> 0.0024247599 | D11: =+B11-C11 -> 0.0076053304 | G11: =+Facility!AM13/Facility!AM$8 -> 0.0058275058 | H11: =+B11-G11 -> 0.0042025844
A12: Self Pay | B12: =+Facility!V14/Facility!V$8 -> 0.014042126 | C12: =+Facility!W14/Facility!W$8 -> 0.011582735 | D12: =+B12-C12 -> 0.0024593915 | G12: =+Facility!AM14/Facility!AM$8 -> 0.013986014 | H12: =+B12-G12 -> 5.6112393e-05
A14: Inpatient Days | B14: =Facility!V29 -> 10382 | C14: =Facility!W29 -> 11113 | D14: =+B14-C14 -> -731 | E14: =+IF(D14=0,0,D14/C14) -> -0.065778818 | G14: =+Facility!AM29 -> 13089 | H14: =+B14-G14 -> -2707 | I14: =+IF(H14=0,0,IF(AND(G14=0,H14>0),-100%,H14/G14)) -> -0.20681488
A15: LOS | B15: =Facility!V32 -> 10.41324 | C15: =Facility!W32 -> 10.020371 | D15: =+B15-C15 -> 0.39286859 | E15: =+IF(D15=0,0,D15/C15) -> 0.03920699 | G15: =+Facility!AM32 -> 15.255245 | H15: =+B15-G15 -> -4.842005 | I15: =+IF(H15=0,0,IF(AND(G15=0,H15>0),-100%,H15/G15)) -> -0.31739937
A16: ADC | B16: =Facility!V33 -> 86.516667 | C16: =Facility!W33 -> 92.608333 | D16: =+B16-C16 -> -6.0916667 | E16: =+IF(D16=0,0,D16/C16) -> -0.065778818 | G16: =+Facility!AM33 -> 109.075 | H16: =+B16-G16 -> -22.558333 | I16: =+IF(H16=0,0,IF(AND(G16=0,H16>0),-100%,H16/G16)) -> -0.20681488
A17: Occupancy | B17: =Facility!V31 -> 1.3954301 | C17: =Facility!W31 -> 1.4936828 | D17: =+B17-C17 -> -0.098252688 | G17: =+Facility!AM31 -> 0.79039855 | H17: =+B17-G17 -> 0.60503156
A18: Equivalent ADC | B18: =Facility!AD34 -> 84.117104 | C18: =Facility!AE34 -> 117.22815 | D18: =+B18-C18 -> -33.111045 | E18: =+IF(D18=0,0,D18/C18) -> -0.28244961 | G18: =Facility!AM34 -> 113.51516 | H18: =+B18-G18 -> -29.398053 | I18: =+IF(H18=0,0,IF(AND(G18=0,H18>0),-100%,H18/G18)) -> -0.2589791
A20: Service Mix (ADC)
A21: Children | B21: =Facility!V55/Facility!V$33 -> 0 | C21: =Facility!W55/Facility!W$33 -> 0 | D21: =+B21-C21 -> 0 | G21: =Facility!AM55/Facility!AM$33 -> 0 | H21: =+B21-G21 -> 0
A22: Pre-Adolescent | B22: =Facility!V56/Facility!V$33 -> 0 | C22: =Facility!W56/Facility!W$33 -> 0 | D22: =+B22-C22 -> 0 | G22: =Facility!AM56/Facility!AM$33 -> 0 | H22: =+B22-G22 -> 0
A23: Adolescent | B23: =Facility!V57/Facility!V$33 -> 0.38595646 | C23: =Facility!W57/Facility!W$33 -> 0.37262665 | D23: =+B23-C23 -> 0.01332981 | G23: =Facility!AM57/Facility!AM$33 -> 0.41653297 | H23: =+B23-G23 -> -0.030576504
A24: Adult | B24: =Facility!V58/Facility!V$33+0.397 -> 0.96596552 | C24: =Facility!W58/Facility!W$33 -> 0.57995141 | D24: =+B24-C24 -> 0.38601411 | G24: =Facility!AM58/Facility!AM$33 -> 0.37726335 | H24: =+B24-G24 -> 0.58870217
A25: Chem Dep | B25: =Facility!V59/Facility!V$33 -> 0 | C25: =Facility!W59/Facility!W$33 -> 0 | D25: =+B25-C25 -> 0 | G25: =Facility!AM59/Facility!AM$33 -> 0 | H25: =+B25-G25 -> 0
A26: Gero | B26: =Facility!V60/Facility!V$33-0.4 -> -0.4 | C26: =Facility!W60/Facility!W$33 -> 0 | D26: =+B26-C26 -> -0.4 | G26: =Facility!AM60/Facility!AM$33 -> 0 | H26: =+B26-G26 -> -0.4
A27: PRTF | B27: =Facility!V61/Facility!V$33 -> 0 | C27: =Facility!W61/Facility!W$33 -> 0 | D27: =+B27-C27 -> 0 | G27: =Facility!AM61/Facility!AM$33 -> 0.16953167 | H27: =+B27-G27 -> -0.16953167
A28: Detox | B28: =Facility!V62/Facility!V$33 -> 0.04507802 | C28: =Facility!W62/Facility!W$33 -> 0.047421938 | D28: =+B28-C28 -> -0.0023439186 | G28: =Facility!AM62/Facility!AM$33 -> 0.036672015 | H28: =+B28-G28 -> 0.008406005
A29: RTC | B29: =Facility!V63/Facility!V$33 -> 0 | C29: =Facility!W63/Facility!W$33 -> 0 | D29: =+B29-C29 -> 0 | G29: =Facility!AM63/Facility!AM$33 -> 0 | H29: =+B29-G29 -> 0
A30: PHP with Boarding | B30: =Facility!V64/Facility!V$33 -> 0 | C30: =Facility!W64/Facility!W$33 -> 0 | D30: =+B30-C30 -> 0 | G30: =Facility!AM64/Facility!AM$33 -> 0 | H30: =+B30-G30 -> 0
A31: IOP with Boarding | B31: =Facility!V65/Facility!V$33 -> 0 | C31: =Facility!W65/Facility!W$33 -> 0 | D31: =+B31-C31 -> 0 | G31: =Facility!AM65/Facility!AM$33 -> 0 | H31: =+B31-G31 -> 0
A33: Outpatient Visits | B33: =Facility!V68 -> 0 | C33: =Facility!W68 -> 0 | D33: =+B33-C33 -> 0 | E33: =+IF(D33=0,0,D33/C33) -> 0 | G33: =+Facility!AM68 -> 0 | H33: =+B33-G33 -> 0 | I33: =+IF(H33=0,0,IF(AND(G33=0,H33>0),-100%,H33/G33)) -> 0
A35: Service Mix (visits)
A36: PHP | B36: =IF(Facility!V70=0,0,Facility!V70/Facility!V$68) -> 0 | C36: =IF(Facility!W70=0,0,Facility!W70/Facility!W$68) -> 0 | D36: =+B36-C36 -> 0 | G36: =IF(Facility!AM70=0,0,Facility!AM70/Facility!AM$68) -> 0 | H36: =+B36-G36 -> 0
A37: IOP | B37: =IF(Facility!V71=0,0,Facility!V71/Facility!V$68) -> 0 | C37: =IF(Facility!W71=0,0,Facility!W71/Facility!W$68) -> 0 | D37: =+B37-C37 -> 0 | G37: =IF(Facility!AM71=0,0,Facility!AM71/Facility!AM$68) -> 0 | H37: =+B37-G37 -> 0
A38: Traditional | B38: =IF(Facility!V72=0,0,Facility!V72/Facility!V$68) -> 0 | C38: =IF(Facility!W72=0,0,Facility!W72/Facility!W$68) -> 0 | D38: =+B38-C38 -> 0 | G38: =IF(Facility!AM72=0,0,Facility!AM72/Facility!AM$68) -> 0 | H38: =+B38-G38 -> 0
A39: ECT/SLE | B39: =IF(Facility!V73=0,0,Facility!V73/Facility!V$68) -> 0 | C39: =IF(Facility!W73=0,0,Facility!W73/Facility!W$68) -> 0 | D39: =+B39-C39 -> 0 | G39: =IF(Facility!AM73=0,0,Facility!AM73/Facility!AM$68) -> 0 | H39: =+B39-G39 -> 0
B42: Actual | C42: Budget | D42: Var | E42: Var % | G42: PYTD | H42: Var | I42: Var %
A44: Net Revenue | B44: =Facility!V78 -> 20656107 | C44: =Facility!W78 -> 22995024 | D44: =+B44-C44 -> -2338917.2 | E44: =+IF(D44=0,0,D44/C44) -> -0.10171406 | G44: =+Facility!AM78 -> 14672444 | H44: =+B44-G44 -> 5983662.9 | I44: =+IF(H44=0,0,IF(AND(G44=0,H44>0),-100%,H44/G44)) -> 0.40781638
A45: Inpatient | B45: =Facility!AL87 -> 20393295 | C45: =Facility!AM87 -> 14061745 | D45: =+B45-C45 -> 6331550.3 | E45: =+IF(D45=0,0,D45/C45) -> 0.45026775 | G45: =Facility!AM87 -> 14061745 | H45: =+B45-G45 -> 6331550.3 | I45: =+IF(H45=0,0,IF(AND(G45=0,H45>0),-100%,H45/G45)) -> 0.45026775
A46: Outpatient | B46: =Facility!AL88 -> 0 | C46: =Facility!AM88 -> 0 | D46: =+B46-C46 -> 0 | E46: =+IF(D46=0,0,D46/C46) -> 0 | G46: =Facility!AM88 -> 0 | H46: =+B46-G46 -> 0 | I46: =+IF(H46=0,0,IF(AND(G46=0,H46>0),-100%,H46/G46)) -> 0
A47: Professional Fee | B47: =Facility!AL89 -> 408004.82 | C47: =Facility!AM89 -> 589530.05 | D47: =+B47-C47 -> -181525.23 | E47: =+IF(D47=0,0,D47/C47) -> -0.30791514 | G47: =Facility!AM89 -> 589530.05 | H47: =+B47-G47 -> -181525.23 | I47: =+IF(H47=0,0,IF(AND(G47=0,H47>0),-100%,H47/G47)) -> -0.30791514
A49: IP Net PPD | B49: =Facility!V87/Facility!V29 -> 1964.2935 | C49: =Facility!W87/Facility!W29 -> 2025.836 | D49: =+B49-C49 -> -61.542446 | E49: =+IF(D49=0,0,D49/C49) -> -0.03037879 | G49: =Facility!AM87/Facility!AM29 -> 1074.3178 | H49: =+B49-G49 -> 889.97577 | I49: =+IF(H49=0,0,IF(AND(G49=0,H49>0),-100%,H49/G49)) -> 0.82841019
A50: OP Net POPV | B50: =IF(Facility!V68=0,0,Facility!V88/Facility!V68) -> 0 | C50: =IF(Facility!W68=0,0,Facility!W88/Facility!W68) -> 0 | D50: =+B50-C50 -> 0 | E50: =+IF(D50=0,0,D50/C50) -> 0 | G50: =IF(Facility!AM68=0,0,Facility!AM88/Facility!AM68) -> 0 | H50: =+B50-G50 -> 0 | I50: =+IF(H50=0,0,IF(AND(G50=0,H50>0),-100%,H50/G50)) -> 0
A52: NR per IP Day | B52: =Facility!V115 -> 1989.6077 | C52: =Facility!W115 -> 2069.2004 | D52: =+B52-C52 -> -79.592727 | E52: =+IF(D52=0,0,D52/C52) -> -0.038465452 | G52: =+Facility!AM115 -> 1120.9752 | H52: =+B52-G52 -> 868.6325 | I52: =+IF(H52=0,0,H52/G52) -> 0.77489005
...

Sheet Mid Month
A1: MTD | B1: =+Facility!B6 -> Acute_DIV1 - Highland Hospital
B3: Mid Month | C3: Budget | D3: Var | E3: Var %
A5: Admissions | B5: =+Facility!AT8 -> 0 | C5: =+Facility!AU8 -> 284.21713 | D5: =+B5-C5 -> -284.21713 | E5: =+IF(D5=0,0,D5/C5) -> -1
A7: Inpatient Days | B7: =+Facility!AT29 -> 0 | C7: =+Facility!AU29 -> 2856 | D7: =+B7-C7 -> -2856 | E7: =+IF(D7=0,0,D7/C7) -> -1
A8: LOS | B8: =+Facility!AT32 -> 0 | C8: =+Facility!AU32 -> 10.048655 | D8: =+B8-C8 -> -10.048655 | E8: =+IF(D8=0,0,D8/C8) -> -1
A9: ADC | B9: =+Facility!AT33 -> 0 | C9: =+Facility!AU33 -> 95.2 | D9: =+B9-C9 -> -95.2 | E9: =+IF(D9=0,0,D9/C9) -> -1
A10: Occupancy | B10: =+Facility!AT31 -> 0 | C10: =+Facility!AU31 -> 0.83508772 | D10: =+B10-C10 -> -0.83508772
A11: Equivalent ADC | B11: =Facility!AT34 -> 0 | C11: =Facility!AU34 -> 97.08282 | D11: =+B11-C11 -> -97.08282 | E11: =+IF(D11=0,0,D11/C11) -> -1
A13: Outpatient Visits | B13: =+Facility!AT68 -> 0 | C13: =+Facility!AU68 -> 0 | D13: =+B13-C13 -> 0 | E13: =+IF(D13=0,0,D13/C13) -> 0
A15: Net Revenue | B15: =+Facility!AT78 -> 0 | C15: =+Facility!AU78 -> 5703208.5 | D15: =+B15-C15 -> -5703208.5 | E15: =+IF(D15=0,0,D15/C15) -> -1
A16: Inpatient | B16: =Facility!AT87 -> 0 | C16: =Facility!AU87 -> 5588382.7 | D16: =+B16-C16 -> -5588382.7 | E16: =+IF(D16=0,0,D16/C16) -> -1
A17: Outpatient | B17: =Facility!AT88 -> 0 | C17: =Facility!AU88 -> 0 | D17: =+B17-C17 -> 0 | E17: =+IF(D17=0,0,D17/C17) -> 0
A18: Professional Fee | B18: =Facility!AT89 -> 0 | C18: =Facility!AU89 -> 110014.62 | D18: =+B18-C18 -> -110014.62 | E18: =+IF(D18=0,0,D18/C18) -> -1
A20: IP Net PPD | B20: =Facility!AT87/Facility!AT29 -> #DIV/0! | C20: =Facility!AU87/Facility!AU29 -> 1956.7166 | D20: =+B20-C20 -> #DIV/0! | E20: =+IF(D20=0,0,D20/C20) -> #DIV/0!
A21: OP Net POPV | B21: =IF(Facility!AT68=0,0,Facility!AT88/Facility!AT68) -> 0 | C21: =IF(Facility!AU68=0,0,Facility!AU88/Facility!AU68) -> 0 | D21: =+B21-C21 -> 0 | E21: =+IF(D21=0,0,D21/C21) -> 0
A23: NR per IP Day | B23: =+Facility!AT115 -> #DIV/0! | C23: =+Facility!AU115 -> 1996.9218 | D23: =+B23-C23 -> #DIV/0! | E23: =+IF(D23=0,0,D23/C23) -> #DIV/0!
A25: EPOB Paid | B25: =+Facility!AT125 -> 0 | C25: =+Facility!AU125 -> 0 | D25: =+C25-B25 -> 0 | E25: =+IF(D25=0,0,D25/C25) -> 0
A26: Equivalent EPOB Paid | B26: =+Facility!AT126 -> 0 | C26: =+Facility!AU126 -> 0 | D26: =+C26-B26 -> 0 | E26: =+IF(D26=0,0,D26/C26) -> 0
A27: Paid FTEs | B27: =Facility!AT136 -> 0 | C27: =Facility!AU136 -> 0 | D27: =+C27-B27 -> 0 | E27: =+IF(D27=0,0,D27/C27) -> 0
A29: Labor Cost | B29: =+Facility!AT138 -> 0 | C29: =+Facility!AU138 -> 119050.98 | D29: =+C29-B29 -> 119050.98 | E29: =+IF(D29=0,0,D29/C29) -> 1
A30: Labor Cost AHR | B30: =+Facility!AT139 -> #DIV/0! | C30: =+Facility!AU139 -> #DIV/0! | D30: =+C30-B30 -> #DIV/0! | E30: =+IF(D30=0,0,D30/C30) -> #DIV/0!
A32: Supplies | B32: =+Facility!AT166 -> 0 | C32: =+Facility!AU166 -> 105597.28 | D32: =+C32-B32 -> 105597.28 | E32: =+IF(D32=0,0,D32/C32) -> 1
A33: - per patient day | B33: =+B32/B7 -> #DIV/0! | C33: =+C32/C7 -> 36.973837 | D33: =+C33-B33 -> #DIV/0! | E33: =+IF(D33=0,0,D33/C33) -> #DIV/0!
A35: Purchased Svc | B35: =+Facility!AT180 -> 0 | C35: =+Facility!AU180 -> 168869.76 | D35: =+C35-B35 -> 168869.76 | E35: =+IF(D35=0,0,D35/C35) -> 1
A36: Pro Fees | B36: =+Facility!AT189 -> 0 | C36: =+Facility!AU189 -> 87492.5 | D36: =+C36-B36 -> 87492.5 | E36: =+IF(D36=0,0,D36/C36) -> 1
A37: Other | B37: =+SUM(Facility!AT201:AT211) -> 0 | C37: =+SUM(Facility!AU201:AU211) -> 961963.56 | D37: =+C37-B37 -> 961963.56 | E37: =+IF(D37=0,0,D37/C37) -> 1
A39: EBITDA | B39: =+Facility!AT215 -> 0 | C39: =+Facility!AU215 -> 4260234.4 | D39: =+B39-C39 -> -4260234.4 | E39: =+IF(D39=0,0,D39/C39) -> -1
A40: EBITDA Margin | B40: =+B39/B15 -> #DIV/0! | C40: =+C39/C15 -> 0.74698907 | D40: =+B40-C40 -> #DIV/0!

Sheet Facility
C2: Scenario | E2: Actual | F2: Budget_Final | M2: =+$E$2 -> Actual | N2: =+$E$2 -> Actual | V2: =E2 -> Actual | W2: =F2 -> Budget_Final | AD2: =+$E$2 -> Actual | AE2: =+$E$2 -> Actual | AL2: =+$E$2 -> Actual | AM2: =+$E$2 -> Actual | AT2: MIDFCST | AU2: =+F2 -> Budget_Final
C3: Time | E3: 2026M4 | F3: =+$E$3 -> 2026M4 | M3: =+$E$3 -> 2026M4 | N3: 2026M3 | V3: =+$E$3 -> 2026M4 | W3: =+$E$3 -> 2026M4 | AD3: =+$E$3 -> 2026M4 | AE3: 2025M4 | AL3: =+$E$3 -> 2026M4 | AM3: =+AE3 -> 2025M4 | AT3: 2026M4 | AU3: =+AT3 -> 2026M4
C4: View | E4: MTD | F4: =+E4 -> MTD | M4: =E4 -> MTD | N4: =M4 -> MTD | V4: YTD | W4: =$V$4 -> YTD | AD4: =E4 -> MTD | AE4: =AD4 -> MTD | AL4: =V4 -> YTD | AM4: =AL4 -> YTD | AT4: =AD4 -> MTD | AU4: =AT4 -> MTD
B6: {=CONCATENATE(A8," - ",_xll.OneStreamExcelAddIn.XFFunctions.XFGetMemberInfo("Description","Entity",B8))} -> Acute_DIV1 - Highland Hospital | E6: =+E2 -> Actual | F6: =+F2 -> Budget_Final | M6: =+M2 -> Actual | N6: =+N2 -> Actual | V6: =+V2 -> Actual | W6: =+W2 -> Budget_Final | AD6: =+AD2 -> Actual | AE6: =+AE2 -> Actual | AL6: =+AL2 -> Actual | AM6: =+AM2 -> Actual | AT6: =+AT2 -> MIDFCST | AU6: =+AU2 -> Budget_Final
A7: UD4 | B7: Entity | C7: Account | D7: Description | E7: =+E3 -> 2026M4 | F7: =+F3 -> 2026M4 | M7: =+M3 -> 2026M4 | N7: =+N3 -> 2026M3 | V7: =+V3 -> 2026M4 | W7: =+W3 -> 2026M4 | AD7: =+AD3 -> 2026M4 | AE7: =+AE3 -> 2025M4 | AL7: =+AL3 -> 2026M4 | AM7: =+AM3 -> 2025M4 | AT7: =+AT3 -> 2026M4 | AU7: =+AU3 -> 2026M4
A8: Acute_DIV1 | B8: 127 | C8: 91005 | D8: IP Admissions | E8: =_xll.OneStreamExcelAddIn.XFFunctions.XFGetCell("True","Consol", $B8,"Tot_Entity","USD",E$2,E$3,E$4,$C8,"TopFlow","Top","Top","Tot_Los","TOT_Dept_WO_Addbacks","Tot_FC",$A8,"Top5","Top6","Reported","Top8") -> 245 | F8: =_xll.OneStreamExcelAddIn.XFFunctions.XFGetCell("True","Consol", $B8,"Tot_Entity","Aggregated",F$2,F$3,F$4,$C8,"TopFlow","Top","Top","Tot_Los","TOT_Dept_WO_Addbacks","TOP3",$A8,"Top5","Top6","Reported","Top8") -> 284.21713 | G8: =+E8-F8 -> -39.217131 | M8: =_xll.OneStreamExcelAddIn.XFFunctions.XFGetCell("True","Consol", $B8,"Tot_Entity","USD",M$2,M$3,M$4,$C8,"TopFlow","Top","Top","Tot_Los","TOT_Dept_WO_Addbacks","Tot_FC",$A8,"Top5","Top6","Reported","Top8") -> 245 | N8: =_xll.OneStreamExcelAddIn.XFFunctions.XFGetCell("True","Consol", $B8,"Tot_Entity","USD",N$2,N$3,N$4,$C8,"TopFlow","Top","Top","Tot_Los","TOT_Dept_WO_Addbacks","Tot_FC",$A8,"Top5","Top6","Reported","Top8") -> 259 | O8: =+M8-N8 -> -14 | V8: =_xll.OneStreamExcelAddIn.XFFunctions.XFGetCell("True","Consol", $B8,"Tot_Entity","USD",V$2,V$3,V$4,$C8,"TopFlow","Top","Top","Tot_Los","TOT_Dept_WO_Addbacks","Tot_FC",$A8,"Top5","Top6","Reported","Top8") -> 997 | W8: =_xll.OneStreamExcelAddIn.XFFunctions.XFGetCell("True","Consol", $B8,"Tot_Entity","Aggregated",W$2,W$3,W$4,$C8,"TopFlow","Top","Top","Tot_Los","TOT_Dept_WO_Addbacks","TOP3",$A8,"Top5","Top6","Reported","Top8") -> 1109.0408 | X8: =+V8-W8 -> -112.04076 | AD8: =_xll.OneStreamExcelAddIn.XFFunctions.XFGetCell("True","Consol", $B8,"Tot_Entity","USD",AD$2,AD$3,AD$4,$C8,"TopFlow","Top","Top","Tot_Los","TOT_Dept_WO_Addbacks","Tot_FC",$A8,"Top5","Top6","Reported","Top8") -> 245 | AE8: =_xll.OneStreamExcelAddIn.XFFunctions.XFGetCell("True","Consol", $B8,"Tot_Entity","USD",AE$2,AE$3,AE$4,$C8,"TopFlow","Top","Top","Tot_Los","TOT_Dept_WO_Addbacks","Tot_FC",$A8,"Top5","Top6","Reported","Top8") -> 237 | AF8: =+AD8-AE8 -> 8 | AL8: =_xll.OneStreamExcelAddIn.XFFunctions.XFGetCell("True","Consol", $B8,"Tot_Entity","USD",AL$2,AL$3,AL$4,$C8,"TopFlow","Top","Top","Tot_Los","TOT_Dept_WO_Addbacks","Tot_FC",$A8,"Top5","Top6","Reported","Top8") -> 997 | AM8: =_xll.OneStreamExcelAddIn.XFFunctions.XFGetCell("True","Consol", $B8,"Tot_Entity","USD",AM$2,AM$3,AM$4,$C8,"TopFlow","Top","Top","Tot_Los","TOT_Dept_WO_Addbacks","Tot_FC",$A8,"Top5","Top6","Reported","Top8") -> 858 | AN8: =+AL8-AM8 -> 139 | AT8: =_xll.OneStreamExcelAddIn.XFFunctions.XFGetCell("True","Consol", $B8,"Tot_Entity","USD",AT$2,AT$3,AT$4,$C8,"TopFlow","Top","Top","Tot_Los","TOT_Dept_WO_Addbacks","Tot_FC",$A8,"Top5","Top6","Reported","Top8") -> 0 | AU8: =_xll.OneStreamExcelAddIn.XFFunctions.XFGetCell("True","Consol", $B8,"Tot_Entity","USD",AU$2,AU$3,AU$4,$C8,"TopFlow","Top","Top","Tot_Los","TOT_Dept_WO_Addbacks","Tot_FC",$A8,"Top5","Top6","Reported","Top8") -> 284.21713 | AV8: =+AT8-AU8 -> -284.21713
A10: =+$A$8 -> Acute_DIV1 | B10: =+$B$8 -> 127 | C10: 91005 | D10: IP Admissions - MEDICARE | E10: =_xll.OneStreamExcelAddIn.XFFunctions.XFGetCell("True","Consol", $B10,"Tot_Entity","USD",E$2,E$3,E$4,$C10,"TopFlow","Top","Top","Tot_Los","TOT_Dept_WO_Addbacks","TOT_Medicare",$A10,"Top5","Top6","Reported","Top8") -> 15 | F10: =_xll.OneStreamExcelAddIn.XFFunctions.XFGetCell("True","Consol", $B10,"Tot_Entity","Aggregated",F$2,F$3,F$4,$C10,"TopFlow","Top","Top","Tot_Los","TOT_Dept_WO_Addbacks","TOT_Medicare",$A10,"Top5","Top6","Reported","Top8") -> 31.318611 | G10: =+E10-F10 -> -16.318611 | M10: =_xll.OneStreamExcelAddIn.XFFunctions.XFGetCell("True","Consol", $B10,"Tot_Entity","USD",M$2,M$3,M$4,$C10,"TopFlow","Top","Top","Tot_Los","TOT_Dept_WO_Addbacks","TOT_Medicare",$A10,"Top5","Top6","Reported","Top8") -> 15 | N10: =_xll.OneStreamExcelAddIn.XFFunctions.XFGetCell("True","Consol", $B10,"Tot_Entity","USD",N$2,N$3,N$4,$C10,"TopFlow","Top","Top","Tot_Los","TOT_Dept_WO_Addbacks","TOT_Medicare",$A10,"Top5","Top6","Reported","Top8") -> 15 | O10: =+M10-N10 -> 0 | V10: =_xll.OneStreamExcelAddIn.XFFunctions.XFGetCell("True","Consol", $B10,"Tot_Entity","USD",V$2,V$3,V$4,$C10,"TopFlow","Top","Top","Tot_Los","TOT_Dept_WO_Addbacks","TOT_Medicare",$A10,"Top5","Top6","Reported","Top8") -> 59 | W10: =_xll.OneStreamExcelAddIn.XFFunctions.XFGetCell("True","Consol", $B10,"Tot_Entity","Aggregated",W$2,W$3,W$4,$C10,"TopFlow","Top","Top","Tot_Los","TOT_Dept_WO_Addbacks","TOT_Medicare",$A10,"Top5","Top6","Reported","Top8") -> 136.4442 | X10: =+V10-W10 -> -77.444196 | AD10: =_xll.OneStreamExcelAddIn.XFFunctions.XFGetCell("True","Consol", $B10,"Tot_Entity","USD",AD$2,AD$3,AD$4,$C10,"TopFlow","Top","Top","Tot_Los","TOT_Dept_WO_Addbacks","TOT_Medicare",$A10,"Top5","Top6","Reported","Top8") -> 15 | AE10: =_xll.OneStreamExcelAddIn.XFFunctions.XFGetCell("True","Consol", $B10,"Tot_Entity","USD",AE$2,AE$3,AE$4,$C10,"TopFlow","Top","Top","Tot_Los","TOT_Dept_WO_Addbacks","TOT_Medicare",$A10,"Top5","Top6","Reported","Top8") -> 25 | AF10: =+AD10-AE10 -> -10 | AL10: =_xll.OneStreamExcelAddIn.XFFunctions.XFGetCell("True","Consol", $B10,"Tot_Entity","USD",AL$2,AL$3,AL$4,$C10,"TopFlow","Top","Top","Tot_Los","TOT_Dept_WO_Addbacks","TOT_Medicare",$A10,"Top5","Top6","Reported","Top8") -> 59 | AM10: =_xll.OneStreamExcelAddIn.XFFunctions.XFGetCell("True","Consol", $B10,"Tot_Entity","USD",AM$2,AM$3,AM$4,$C10,"TopFlow","Top","Top","Tot_Los","TOT_Dept_WO_Addbacks","TOT_Medicare",$A10,"Top5","Top6","Reported","Top8") -> 81 | AN10: =+AL10-AM10 -> -22 | AT10: =_xll.OneStreamExcelAddIn.XFFunctions.XFGetCell("True","Consol", $B10,"Tot_Entity","USD",AT$2,AT$3,AT$4,$C10,"TopFlow","Top","Top","Tot_Los","TOT_Dept_WO_Addbacks","TOT_Medicare",$A10,"Top5","Top6","Reported","Top8") -> 0 | AU10: =_xll.OneStreamExcelAddIn.XFFunctions.XFGetCell("True","Consol", $B10,"Tot_Entity","USD",AU$2,AU$3,AU$4,$C10,"TopFlow","Top","Top","Tot_Los","TOT_Dept_WO_Addbacks","TOT_Medicare",$A10,"Top5","Top6","Reported","Top8") -> 31.318611 | AV10: =+AT10-AU10 -> -31.318611
A11: =+$A$8 -> Acute_DIV1 | B11: =+$B$8 -> 127 | C11: 91005 | D11: IP Admissions - MEDICAID | E11: =_xll.OneStreamExcelAddIn.XFFunctions.XFGetCell("True","Consol", $B11,"Tot_Entity","USD",E$2,E$3,E$4,$C11,"TopFlow","Top","Top","Tot_Los","TOT_Dept_WO_Addbacks","TOT_Medicaid",$A11,"Top5","Top6","Reported","Top8") -> 173 | F11: =_xll.OneStreamExcelAddIn.XFFunctions.XFGetCell("True","Consol", $B11,"Tot_Entity","Aggregated",F$2,F$3,F$4,$C11,"TopFlow","Top","Top","Tot_Los","TOT_Dept_WO_Addbacks","TOT_Medicaid",$A11,"Top5","Top6","Reported","Top8") -> 167.99132 | G11: =+E11-F11 -> 5.0086761 | M11: =_xll.OneStreamExcelAddIn.XFFunctions.XFGetCell("True","Consol", $B11,"Tot_Entity","USD",M$2,M$3,M$4,$C11,"TopFlow","Top","Top","Tot_Los","TOT_Dept_WO_Addbacks","TOT_Medicaid",$A11,"Top5","Top6","Reported","Top8") -> 173 | N11: =_xll.OneStreamExcelAddIn.XFFunctions.XFGetCell("True","Consol", $B11,"Tot_Entity","USD",N$2,N$3,N$4,$C11,"TopFlow","Top","Top","Tot_Los","TOT_Dept_WO_Addbacks","TOT_Medicaid",$A11,"Top5","Top6","Reported","Top8") -> 191 | O11: =+M11-N11 -> -18 | V11: =_xll.OneStreamExcelAddIn.XFFunctions.XFGetCell("True","Consol", $B11,"Tot_Entity","USD",V$2,V$3,V$4,$C11,"TopFlow","Top","Top","Tot_Los","TOT_Dept_WO_Addbacks","TOT_Medicaid",$A11,"Top5","Top6","Reported","Top8") -> 741 | W11: =_xll.OneStreamExcelAddIn.XFFunctions.XFGetCell("True","Consol", $B11,"Tot_Entity","Aggregated",W$2,W$3,W$4,$C11,"TopFlow","Top","Top","Tot_Los","TOT_Dept_WO_Addbacks","TOT_Medicaid",$A11,"Top5","Top6","Reported","Top8") -> 721.3413 | X11: =+V11-W11 -> 19.658705 | AD11: =_xll.OneStreamExcelAddIn.XFFunctions.XFGetCell("True","Consol", $B11,"Tot_Entity","USD",AD$2,AD$3,AD$4,$C11,"TopFlow","Top","Top","Tot_Los","TOT_Dept_WO_Addbacks","TOT_Medicaid",$A11,"Top5","Top6","Reported","Top8") -> 173 | AE11: =_xll.OneStreamExcelAddIn.XFFunctions.XFGetCell("True","Consol", $B11,"Tot_Entity","USD",AE$2,AE$3,AE$4,$C11,"TopFlow","Top","Top","Tot_Los","TOT_Dept_WO_Addbacks","TOT_Medicaid",$A11,"Top5","Top6","Reported","Top8") -> 161 | AF11: =+AD11-AE11 -> 12 | AL11: =_xll.OneStreamExcelAddIn.XFFunctions.XFGetCell("True","Consol", $B11,"Tot_Entity","USD",AL$2,AL$3,AL$4,$C11,"TopFlow","Top","Top","Tot_Los","TOT_Dept_WO_Addbacks","TOT_Medicaid",$A11,"Top5","Top6","Reported","Top8") -> 741 | AM11: =_xll.OneStreamExcelAddIn.XFFunctions.XFGetCell("True","Consol", $B11,"Tot_Entity","USD",AM$2,AM$3,AM$4,$C11,"TopFlow","Top","Top","Tot_Los","TOT_Dept_WO_Addbacks","TOT_Medicaid",$A11,"Top5","Top6","Reported","Top8") -> 587 | AN11: =+AL11-AM11 -> 154 | AT11: =_xll.OneStreamExcelAddIn.XFFunctions.XFGetCell("True","Consol", $B11,"Tot_Entity","USD",AT$2,AT$3,AT$4,$C11,"TopFlow","Top","Top","Tot_Los","TOT_Dept_WO_Addbacks","TOT_Medicaid",$A11,"Top5","Top6","Reported","Top8") -> 0 | AU11: =_xll.OneStreamExcelAddIn.XFFunctions.XFGetCell("True","Consol", $B11,"Tot_Entity","USD",AU$2,AU$3,AU$4,$C11,"TopFlow","Top","Top","Tot_Los","TOT_Dept_WO_Addbacks","TOT_Medicaid",$A11,"Top5","Top6","Reported","Top8") -> 167.99132 | AV11: =+AT11-AU11 -> -167.99132
A12: =+$A$8 -> Acute_DIV1 | B12: =+$B$8 -> 127 | C12: 91005 | D12: IP Admissions - COMMERCIAL | E12: =_xll.OneStreamExcelAddIn.XFFunctions.XFGetCell("True","Consol", $B12,"Tot_Entity","USD",E$2,E$3,E$4,$C12,"TopFlow","Top","Top","Tot_Los","TOT_Dept_WO_Addbacks","TOT_Comm",$A12,"Top5","Top6","Reported","Top8") -> 49 | F12: =_xll.OneStreamExcelAddIn.XFFunctions.XFGetCell("True","Consol", $B12,"Tot_Entity","Aggregated",F$2,F$3,F$4,$C12,"TopFlow","Top","Top","Tot_Los","TOT_Dept_WO_Addbacks","TOT_Comm",$A12,"Top5","Top6","Reported","Top8") -> 76.964824 | G12: =+E12-F12 -> -27.964824 | M12: =_xll.OneStreamExcelAddIn.XFFunctions.XFGetCell("True","Consol", $B12,"Tot_Entity","USD",M$2,M$3,M$4,$C12,"TopFlow","Top","Top","Tot_Los","TOT_Dept_WO_Addbacks","TOT_Comm",$A12,"Top5","Top6","Reported","Top8") -> 49 | N12: =_xll.OneStreamExcelAddIn.XFFunctions.XFGetCell("True","Consol", $B12,"Tot_Entity","USD",N$2,N$3,N$4,$C12,"TopFlow","Top","Top","Tot_Los","TOT_Dept_WO_Addbacks","TOT_Comm",$A12,"Top5","Top6","Reported","Top8") -> 50 | O12: =+M12-N12 -> -1 | V12: =_xll.OneStreamExcelAddIn.XFFunctions.XFGetCell("True","Consol", $B12,"Tot_Entity","USD",V$2,V$3,V$4,$C12,"TopFlow","Top","Top","Tot_Los","TOT_Dept_WO_Addbacks","TOT_Comm",$A12,"Top5","Top6","Reported","Top8") -> 173 | W12: =_xll.OneStreamExcelAddIn.XFFunctions.XFGetCell("True","Consol", $B12,"Tot_Entity","Aggregated",W$2,W$3,W$4,$C12,"TopFlow","Top","Top","Tot_Los","TOT_Dept_WO_Addbacks","TOT_Comm",$A12,"Top5","Top6","Reported","Top8") -> 235.72039 | X12: =+V12-W12 -> -62.720386 | AD12: =_xll.OneStreamExcelAddIn.XFFunctions.XFGetCell("True","Consol", $B12,"Tot_Entity","USD",AD$2,AD$3,AD$4,$C12,"TopFlow","Top","Top","Tot_Los","TOT_Dept_WO_Addbacks","TOT_Comm",$A12,"Top5","Top6","Reported","Top8") -> 49 | AE12: =_xll.OneStreamExcelAddIn.XFFunctions.XFGetCell("True","Consol", $B12,"Tot_Entity","USD",AE$2,AE$3,AE$4,$C12,"TopFlow","Top","Top","Tot_Los","TOT_Dept_WO_Addbacks","TOT_Comm",$A12,"Top5","Top6","Reported","Top8") -> 44 | AF12: =+AD12-AE12 -> 5 | AL12: =_xll.OneStreamExcelAddIn.XFFunctions.XFGetCell("True","Consol", $B12,"Tot_Entity","USD",AL$2,AL$3,AL$4,$C12,"TopFlow","Top","Top","Tot_Los","TOT_Dept_WO_Addbacks","TOT_Comm",$A12,"Top5","Top6","Reported","Top8") -> 173 | AM12: =_xll.OneStreamExcelAddIn.XFFunctions.XFGetCell("True","Consol", $B12,"Tot_Entity","USD",AM$2,AM$3,AM$4,$C12,"TopFlow","Top","Top","Tot_Los","TOT_Dept_WO_Addbacks","TOT_Comm",$A12,"Top5","Top6","Reported","Top8") -> 173 | AN12: =+AL12-AM12 -> 0 | AT12: =_xll.OneStreamExcelAddIn.XFFunctions.XFGetCell("True","Consol", $B12,"Tot_Entity","USD",AT$2,AT$3,AT$4,$C12,"TopFlow","Top","Top","Tot_Los","TOT_Dept_WO_Addbacks","TOT_Comm",$A12,"Top5","Top6","Reported","Top8") -> 0 | AU12: =_xll.OneStreamExcelAddIn.XFFunctions.XFGetCell("True","Consol", $B12,"Tot_Entity","USD",AU$2,AU$3,AU$4,$C12,"TopFlow","Top","Top","Tot_Los","TOT_Dept_WO_Addbacks","TOT_Comm",$A12,"Top5","Top6","Reported","Top8") -> 76.964824 | AV12: =+AT12-AU12 -> -76.964824
A13: =+$A$8 -> Acute_DIV1 | B13: =+$B$8 -> 127 | C13: 91005 | D13: IP Admissions - OTHER GOVERNMENT | E13: =_xll.OneStreamExcelAddIn.XFFunctions.XFGetCell("True","Consol", $B13,"Tot_Entity","USD",E$2,E$3,E$4,$C13,"TopFlow","Top","Top","Tot_Los","TOT_Dept_WO_Addbacks","TOT_Oth_Govt",$A13,"Top5","Top6","Reported","Top8") -> 3 | F13: =_xll.OneStreamExcelAddIn.XFFunctions.XFGetCell("True","Consol", $B13,"Tot_Entity","Aggregated",F$2,F$3,F$4,$C13,"TopFlow","Top","Top","Tot_Los","TOT_Dept_WO_Addbacks","TOT_Oth_Govt",$A13,"Top5","Top6","Reported","Top8") -> 1.7615385 | G13: =+E13-F13 -> 1.2384615 | M13: =_xll.OneStreamExcelAddIn.XFFunctions.XFGetCell("True","Consol", $B13,"Tot_Entity","USD",M$2,M$3,M$4,$C13,"TopFlow","Top","Top","Tot_Los","TOT_Dept_WO_Addbacks","TOT_Oth_Govt",$A13,"Top5","Top6","Reported","Top8") -> 3 | N13: =_xll.OneStreamExcelAddIn.XFFunctions.XFGetCell("True","Consol", $B13,"Tot_Entity","USD",N$2,N$3,N$4,$C13,"TopFlow","Top","Top","Tot_Los","TOT_Dept_WO_Addbacks","TOT_Oth_Govt",$A13,"Top5","Top6","Reported","Top8") -> 2 | O13: =+M13-N13 -> 1 | V13: =_xll.OneStreamExcelAddIn.XFFunctions.XFGetCell("True","Consol", $B13,"Tot_Entity","USD",V$2,V$3,V$4,$C13,"TopFlow","Top","Top","Tot_Los","TOT_Dept_WO_Addbacks","TOT_Oth_Govt",$A13,"Top5","Top6","Reported","Top8") -> 10 | W13: =_xll.OneStreamExcelAddIn.XFFunctions.XFGetCell("True","Consol", $B13,"Tot_Entity","Aggregated",W$2,W$3,W$4,$C13,"TopFlow","Top","Top","Tot_Los","TOT_Dept_WO_Addbacks","TOT_Oth_Govt",$A13,"Top5","Top6","Reported","Top8") -> 2.6891575 | X13: =+V13-W13 -> 7.3108425 | AD13: =_xll.OneStreamExcelAddIn.XFFunctions.XFGetCell("True","Consol", $B13,"Tot_Entity","USD",AD$2,AD$3,AD$4,$C13,"TopFlow","Top","Top","Tot_Los","TOT_Dept_WO_Addbacks","TOT_Oth_Govt",$A13,"Top5","Top6","Reported","Top8") -> 3 | AE13: =_xll.OneStreamExcelAddIn.XFFunctions.XFGetCell("True","Consol", $B13,"Tot_Entity","USD",AE$2,AE$3,AE$4,$C13,"TopFlow","Top","Top","Tot_Los","TOT_Dept_WO_Addbacks","TOT_Oth_Govt",$A13,"Top5","Top6","Reported","Top8") -> 2 | AF13: =+AD13-AE13 -> 1 | AL13: =_xll.OneStreamExcelAddIn.XFFunctions.XFGetCell("True","Consol", $B13,"Tot_Entity","USD",AL$2,AL$3,AL$4,$C13,"TopFlow","Top","Top","Tot_Los","TOT_Dept_WO_Addbacks","TOT_Oth_Govt",$A13,"Top5","Top6","Reported","Top8") -> 10 | AM13: =_xll.OneStreamExcelAddIn.XFFunctions.XFGetCell("True","Consol", $B13,"Tot_Entity","USD",AM$2,AM$3,AM$4,$C13,"TopFlow","Top","Top","Tot_Los","TOT_Dept_WO_Addbacks","TOT_Oth_Govt",$A13,"Top5","Top6","Reported","Top8") -> 5 | AN13: =+AL13-AM13 -> 5 | AT13: =_xll.OneStreamExcelAddIn.XFFunctions.XFGetCell("True","Consol", $B13,"Tot_Entity","USD",AT$2,AT$3,AT$4,$C13,"TopFlow","Top","Top","Tot_Los","TOT_Dept_WO_Addbacks","TOT_Oth_Govt",$A13,"Top5","Top6","Reported","Top8") -> 0 | AU13: =_xll.OneStreamExcelAddIn.XFFunctions.XFGetCell("True","Consol", $B13,"Tot_Entity","USD",AU$2,AU$3,AU$4,$C13,"TopFlow","Top","Top","Tot_Los","TOT_Dept_WO_Addbacks","TOT_Oth_Govt",$A13,"Top5","Top6","Reported","Top8") -> 1.7615385 | AV13: =+AT13-AU13 -> -1.7615385
A14: =+$A$8 -> Acute_DIV1 | B14: =+$B$8 -> 127 | C14: 91005 | D14: IP Admissions - SELF PAY | E14: =_xll.OneStreamExcelAddIn.XFFunctions.XFGetCell("True","Consol", $B14,"Tot_Entity","USD",E$2,E$3,E$4,$C14,"TopFlow","Top","Top","Tot_Los","TOT_Dept_WO_Addbacks","TOT_Self_Pay_Oth",$A14,"Top5","Top6","Reported","Top8") -> 5 | F14: =_xll.OneStreamExcelAddIn.XFFunctions.XFGetCell("True","Consol", $B14,"Tot_Entity","Aggregated",F$2,F$3,F$4,$C14,"TopFlow","Top","Top","Tot_Los","TOT_Dept_WO_Addbacks","TOT_Self_Pay_Oth",$A14,"Top5","Top6","Reported","Top8") -> 6.1808333 | G14: =+E14-F14 -> -1.1808333 | M14: =_xll.OneStreamExcelAddIn.XFFunctions.XFGetCell("True","Consol", $B14,"Tot_Entity","USD",M$2,M$3,M$4,$C14,"TopFlow","Top","Top","Tot_Los","TOT_Dept_WO_Addbacks","TOT_Self_Pay_Oth",$A14,"Top5","Top6","Reported","Top8") -> 5 | N14: =_xll.OneStreamExcelAddIn.XFFunctions.XFGetCell("True","Consol", $B14,"Tot_Entity","USD",N$2,N$3,N$4,$C14,"TopFlow","Top","Top","Tot_Los","TOT_Dept_WO_Addbacks","TOT_Self_Pay_Oth",$A14,"Top5","Top6","Reported","Top8") -> 1 | O14: =+M14-N14 -> 4 | V14: =_xll.OneStreamExcelAddIn.XFFunctions.XFGetCell("True","Consol", $B14,"Tot_Entity","USD",V$2,V$3,V$4,$C14,"TopFlow","Top","Top","Tot_Los","TOT_Dept_WO_Addbacks","TOT_Self_Pay_Oth",$A14,"Top5","Top6","Reported","Top8") -> 14 | W14: =_xll.OneStreamExcelAddIn.XFFunctions.XFGetCell("True","Consol", $B14,"Tot_Entity","Aggregated",W$2,W$3,W$4,$C14,"TopFlow","Top","Top","Tot_Los","TOT_Dept_WO_Addbacks","TOT_Self_Pay_Oth",$A14,"Top5","Top6","Reported","Top8") -> 12.845725 | X14: =+V14-W14 -> 1.1542749 | AD14: =_xll.OneStreamExcelAddIn.XFFunctions.XFGetCell("True","Consol", $B14,"Tot_Entity","USD",AD$2,AD$3,AD$4,$C14,"TopFlow","Top","Top","Tot_Los","TOT_Dept_WO_Addbacks","TOT_Self_Pay_Oth",$A14,"Top5","Top6","Reported","Top8") -> 5 | AE14: =_xll.OneStreamExcelAddIn.XFFunctions.XFGetCell("True","Consol", $B14,"Tot_Entity","USD",AE$2,AE$3,AE$4,$C14,"TopFlow","Top","Top","Tot_Los","TOT_Dept_WO_Addbacks","TOT_Self_Pay_Oth",$A14,"Top5","Top6","Reported","Top8") -> 5 | AF14: =+AD14-AE14 -> 0 | AL14: =_xll.OneStreamExcelAddIn.XFFunctions.XFGetCell("True","Consol", $B14,"Tot_Entity","USD",AL$2,AL$3,AL$4,$C14,"TopFlow","Top","Top","Tot_Los","TOT_Dept_WO_Addbacks","TOT_Self_Pay_Oth",$A14,"Top5","Top6","Reported","Top8") -> 14 | AM14: =_xll.OneStreamExcelAddIn.XFFunctions.XFGetCell("True","Consol", $B14,"Tot_Entity","USD",AM$2,AM$3,AM$4,$C14,"TopFlow","Top","Top","Tot_Los","TOT_Dept_WO_Addbacks","TOT_Self_Pay_Oth",$A14,"Top5","Top6","Reported","Top8") -> 12 | AN14: =+AL14-AM14 -> 2 | AT14: =_xll.OneStreamExcelAddIn.XFFunctions.XFGetCell("True","Consol", $B14,"Tot_Entity","USD",AT$2,AT$3,AT$4,$C14,"TopFlow","Top","Top","Tot_Los","TOT_Dept_WO_Addbacks","TOT_Self_Pay_Oth",$A14,"Top5","Top6","Reported","Top8") -> 0 | AU14: =_xll.OneStreamExcelAddIn.XFFunctions.XFGetCell("True","Consol", $B14,"Tot_Entity","USD",AU$2,AU$3,AU$4,$C14,"TopFlow","Top","Top","Tot_Los","TOT_Dept_WO_Addbacks","TOT_Self_Pay_Oth",$A14,"Top5","Top6","Reported","Top8") -> 6.1808333 | AV14: =+AT14-AU14 -> -6.1808333
E15: =E8=SUM(E10:E14) -> TRUE | F15: =F8=SUM(F10:F14) -> TRUE | M15: =M8=SUM(M10:M14) -> TRUE | N15: =N8=SUM(N10:N14) -> TRUE | V15: =V8=SUM(V10:V14) -> TRUE | W15: =W8=SUM(W10:W14) -> TRUE | AD15: =AD8=SUM(AD10:AD14) -> TRUE | AE15: =AE8=SUM(AE10:AE14) -> TRUE | AL15: =AL8=SUM(AL10:AL14) -> TRUE | AM15: =AM8=SUM(AM10:AM14) -> TRUE | AT15: =AT8=SUM(AT10:AT14) -> TRUE | AU15: =AU8=SUM(AU10:AU14) -> TRUE
A17: =+$A$8 -> Acute_DIV1 | B17: =+$B$8 -> 127 | C17: 91005 | D17: Total IP Children | E17: =_xll.OneStreamExcelAddIn.XFFunctions.XFGetCell("True","Consol", $B17,"Tot_Entity","USD",E$2,E$3,E$4,$C17,"TopFlow","Top","Top","Tot_Los","TOT_IP_Child","Tot_FC",$A17,"Top5","Top6","Reported","Top8") -> 0 | F17: =_xll.OneStreamExcelAddIn.XFFunctions.XFGetCell("True","Consol", $B17,"Tot_Entity","Aggregated",F$2,F$3,F$4,$C17,"TopFlow","Top","Top","Tot_Los","TOT_IP_Child","TOP3",$A17,"Top5","Top6","Reported","Top8") -> 0 | G17: =+E17-F17 -> 0 | M17: =_xll.OneStreamExcelAddIn.XFFunctions.XFGetCell("True","Consol", $B17,"Tot_Entity","USD",M$2,M$3,M$4,$C17,"TopFlow","Top","Top","Tot_Los","TOT_IP_Child","Tot_FC",$A17,"Top5","Top6","Reported","Top8") -> 0 | N17: =_xll.OneStreamExcelAddIn.XFFunctions.XFGetCell("True","Consol", $B17,"Tot_Entity","USD",N$2,N$3,N$4,$C17,"TopFlow","Top","Top","Tot_Los","TOT_IP_Child","Tot_FC",$A17,"Top5","Top6","Reported","Top8") -> 0 | O17: =+M17-N17 -> 0 | V17: =_xll.OneStreamExcelAddIn.XFFunctions.XFGetCell("True","Consol", $B17,"Tot_Entity","USD",V$2,V$3,V$4,$C17,"TopFlow","Top","Top","Tot_Los","TOT_IP_Child","Tot_FC",$A17,"Top5","Top6","Reported","Top8") -> 0 | W17: =_xll.OneStreamExcelAddIn.XFFunctions.XFGetCell("True","Consol", $B17,"Tot_Entity","Aggregated",W$2,W$3,W$4,$C17,"TopFlow","Top","Top","Tot_Los","TOT_IP_Child","TOP3",$A17,"Top5","Top6","Reported","Top8") -> 0 | X17: =+V17-W17 -> 0 | AD17: =_xll.OneStreamExcelAddIn.XFFunctions.XFGetCell("True","Consol", $B17,"Tot_Entity","USD",AD$2,AD$3,AD$4,$C17,"TopFlow","Top","Top","Tot_Los","TOT_IP_Child","Tot_FC",$A17,"Top5","Top6","Reported","Top8") -> 0 | AE17: =_xll.OneStreamExcelAddIn.XFFunctions.XFGetCell("True","Consol", $B17,"Tot_Entity","USD",AE$2,AE$3,AE$4,$C17,"TopFlow","Top","Top","Tot_Los","TOT_IP_Child","Tot_FC",$A17,"Top5","Top6","Reported","Top8") -> 0 | AF17: =+AD17-AE17 -> 0 | AL17: =_xll.OneStreamExcelAddIn.XFFunctions.XFGetCell("True","Consol", $B17,"Tot_Entity","USD",AL$2,AL$3,AL$4,$C17,"TopFlow","Top","Top","Tot_Los","TOT_IP_Child","Tot_FC",$A17,"Top5","Top6","Reported","Top8") -> 0 | AM17: =_xll.OneStreamExcelAddIn.XFFunctions.XFGetCell("True","Consol", $B17,"Tot_Entity","USD",AM$2,AM$3,AM$4,$C17,"TopFlow","Top","Top","Tot_Los","TOT_IP_Child","Tot_FC",$A17,"Top5","Top6","Reported","Top8") -> 0 | AN17: =+AL17-AM17 -> 0 | AT17: =_xll.OneStreamExcelAddIn.XFFunctions.XFGetCell("True","Consol", $B17,"Tot_Entity","USD",AT$2,AT$3,AT$4,$C17,"TopFlow","Top","Top","Tot_Los","TOT_IP_Child","Tot_FC",$A17,"Top5","Top6","Reported","Top8") -> 0 | AU17: =_xll.OneStreamExcelAddIn.XFFunctions.XFGetCell("True","Consol", $B17,"Tot_Entity","USD",AU$2,AU$3,AU$4,$C17,"TopFlow","Top","Top","Tot_Los","TOT_IP_Child","Tot_FC",$A17,"Top5","Top6","Reported","Top8") -> 0 | AV17: =+AT17-AU17 -> 0
A18: =+$A$8 -> Acute_DIV1 | B18: =+$B$8 -> 127 | C18: 91005 | D18: Total IP Pre-Adolescent | E18: =_xll.OneStreamExcelAddIn.XFFunctions.XFGetCell("True","Consol", $B18,"Tot_Entity","USD",E$2,E$3,E$4,$C18,"TopFlow","Top","Top","Tot_Los","TOT_IP_Pre_Adolescent","Tot_FC",$A18,"Top5","Top6","Reported","Top8") -> 0 | F18: =_xll.OneStreamExcelAddIn.XFFunctions.XFGetCell("True","Consol", $B18,"Tot_Entity","Aggregated",F$2,F$3,F$4,$C18,"TopFlow","Top","Top","Tot_Los","TOT_IP_Pre_Adolescent","TOP3",$A18,"Top5","Top6","Reported","Top8") -> 0 | G18: =+E18-F18 -> 0 | M18: =_xll.OneStreamExcelAddIn.XFFunctions.XFGetCell("True","Consol", $B18,"Tot_Entity","USD",M$2,M$3,M$4,$C18,"TopFlow","Top","Top","Tot_Los","TOT_IP_Pre_Adolescent","Tot_FC",$A18,"Top5","Top6","Reported","Top8") -> 0 | N18: =_xll.OneStreamExcelAddIn.XFFunctions.XFGetCell("True","Consol", $B18,"Tot_Entity","USD",N$2,N$3,N$4,$C18,"TopFlow","Top","Top","Tot_Los","TOT_IP_Pre_Adolescent","Tot_FC",$A18,"Top5","Top6","Reported","Top8") -> 0 | O18: =+M18-N18 -> 0 | V18: =_xll.OneStreamExcelAddIn.XFFunctions.XFGetCell("True","Consol", $B18,"Tot_Entity","USD",V$2,V$3,V$4,$C18,"TopFlow","Top","Top","Tot_Los","TOT_IP_Pre_Adolescent","Tot_FC",$A18,"Top5","Top6","Reported","Top8") -> 0 | W18: =_xll.OneStreamExcelAddIn.XFFunctions.XFGetCell("True","Consol", $B18,"Tot_Entity","Aggregated",W$2,W$3,W$4,$C18,"TopFlow","Top","Top","Tot_Los","TOT_IP_Pre_Adolescent","TOP3",$A18,"Top5","Top6","Reported","Top8") -> 0 | X18: =+V18-W18 -> 0 | AD18: =_xll.OneStreamExcelAddIn.XFFunctions.XFGetCell("True","Consol", $B18,"Tot_Entity","USD",AD$2,AD$3,AD$4,$C18,"TopFlow","Top","Top","Tot_Los","TOT_IP_Pre_Adolescent","Tot_FC",$A18,"Top5","Top6","Reported","Top8") -> 0 | AE18: =_xll.OneStreamExcelAddIn.XFFunctions.XFGetCell("True","Consol", $B18,"Tot_Entity","USD",AE$2,AE$3,AE$4,$C18,"TopFlow","Top","Top","Tot_Los","TOT_IP_Pre_Adolescent","Tot_FC",$A18,"Top5","Top6","Reported","Top8") -> 0 | AF18: =+AD18-AE18 -> 0 | AL18: =_xll.OneStreamExcelAddIn.XFFunctions.XFGetCell("True","Consol", $B18,"Tot_Entity","USD",AL$2,AL$3,AL$4,$C18,"TopFlow","Top","Top","Tot_Los","TOT_IP_Pre_Adolescent","Tot_FC",$A18,"Top5","Top6","Reported","Top8") -> 0 | AM18: =_xll.OneStreamExcelAddIn.XFFunctions.XFGetCell("True","Consol", $B18,"Tot_Entity","USD",AM$2,AM$3,AM$4,$C18,"TopFlow","Top","Top","Tot_Los","TOT_IP_Pre_Adolescent","Tot_FC",$A18,"Top5","Top6","Reported","Top8") -> 0 | AN18: =+AL18-AM18 -> 0 | AT18: =_xll.OneStreamExcelAddIn.XFFunctions.XFGetCell("True","Consol", $B18,"Tot_Entity","USD",AT$2,AT$3,AT$4,$C18,"TopFlow","Top","Top","Tot_Los","TOT_IP_Pre_Adolescent","Tot_FC",$A18,"Top5","Top6","Reported","Top8") -> 0 | AU18: =_xll.OneStreamExcelAddIn.XFFunctions.XFGetCell("True","Consol", $B18,"Tot_Entity","USD",AU$2,AU$3,AU$4,$C18,"TopFlow","Top","Top","Tot_Los","TOT_IP_Pre_Adolescent","Tot_FC",$A18,"Top5","Top6","Reported","Top8") -> 0 | AV18: =+AT18-AU18 -> 0
A19: =+$A$8 -> Acute_DIV1 | B19: =+$B$8 -> 127 | C19: 91005 | D19: Total IP Adolescent | E19: =_xll.OneStreamExcelAddIn.XFFunctions.XFGetCell("True","Consol", $B19,"Tot_Entity","USD",E$2,E$3,E$4,$C19,"TopFlow","Top","Top","Tot_Los","TOT_IP_Adolescent","Tot_FC",$A19,"Top5","Top6","Reported","Top8") -> 101 | F19: =_xll.OneStreamExcelAddIn.XFFunctions.XFGetCell("True","Consol", $B19,"Tot_Entity","Aggregated",F$2,F$3,F$4,$C19,"TopFlow","Top","Top","Tot_Los","TOT_IP_Adolescent","TOP3",$A19,"Top5","Top6","Reported","Top8") -> 99.419051 | G19: =+E19-F19 -> 1.5809489 | M19: =_xll.OneStreamExcelAddIn.XFFunctions.XFGetCell("True","Consol", $B19,"Tot_Entity","USD",M$2,M$3,M$4,$C19,"TopFlow","Top","Top","Tot_Los","TOT_IP_Adolescent","Tot_FC",$A19,"Top5","Top6","Reported","Top8") -> 101 | N19: =_xll.OneStreamExcelAddIn.XFFunctions.XFGetCell("True","Consol", $B19,"Tot_Entity","USD",N$2,N$3,N$4,$C19,"TopFlow","Top","Top","Tot_Los","TOT_IP_Adolescent","Tot_FC",$A19,"Top5","Top6","Reported","Top8") -> 97 | O19: =+M19-N19 -> 4 | V19: =_xll.OneStreamExcelAddIn.XFFunctions.XFGetCell("True","Consol", $B19,"Tot_Entity","USD",V$2,V$3,V$4,$C19,"TopFlow","Top","Top","Tot_Los","TOT_IP_Adolescent","Tot_FC",$A19,"Top5","Top6","Reported","Top8") -> 374 | W19: =_xll.OneStreamExcelAddIn.XFFunctions.XFGetCell("True","Consol", $B19,"Tot_Entity","Aggregated",W$2,W$3,W$4,$C19,"TopFlow","Top","Top","Tot_Los","TOT_IP_Adolescent","TOP3",$A19,"Top5","Top6","Reported","Top8") -> 373.31481 | X19: =+V19-W19 -> 0.68519134 | AD19: =_xll.OneStreamExcelAddIn.XFFunctions.XFGetCell("True","Consol", $B19,"Tot_Entity","USD",AD$2,AD$3,AD$4,$C19,"TopFlow","Top","Top","Tot_Los","TOT_IP_Adolescent","Tot_FC",$A19,"Top5","Top6","Reported","Top8") -> 101 | AE19: =_xll.OneStreamExcelAddIn.XFFunctions.XFGetCell("True","Consol", $B19,"Tot_Entity","USD",AE$2,AE$3,AE$4,$C19,"TopFlow","Top","Top","Tot_Los","TOT_IP_Adolescent","Tot_FC",$A19,"Top5","Top6","Reported","Top8") -> 82 | AF19: =+AD19-AE19 -> 19 | AL19: =_xll.OneStreamExcelAddIn.XFFunctions.XFGetCell("True","Consol", $B19,"Tot_Entity","USD",AL$2,AL$3,AL$4,$C19,"TopFlow","Top","Top","Tot_Los","TOT_IP_Adolescent","Tot_FC",$A19,"Top5","Top6","Reported","Top8") -> 374 | AM19: =_xll.OneStreamExcelAddIn.XFFunctions.XFGetCell("True","Consol", $B19,"Tot_Entity","USD",AM$2,AM$3,AM$4,$C19,"TopFlow","Top","Top","Tot_Los","TOT_IP_Adolescent","Tot_FC",$A19,"Top5","Top6","Reported","Top8") -> 245 | AN19: =+AL19-AM19 -> 129 | AT19: =_xll.OneStreamExcelAddIn.XFFunctions.XFGetCell("True","Consol", $B19,"Tot_Entity","USD",AT$2,AT$3,AT$4,$C19,"TopFlow","Top","Top","Tot_Los","TOT_IP_Adolescent","Tot_FC",$A19,"Top5","Top6","Reported","Top8") -> 0 | AU19: =_xll.OneStreamExcelAddIn.XFFunctions.XFGetCell("True","Consol", $B19,"Tot_Entity","USD",AU$2,AU$3,AU$4,$C19,"TopFlow","Top","Top","Tot_Los","TOT_IP_Adolescent","Tot_FC",$A19,"Top5","Top6","Reported","Top8") -> 99.419051 | AV19: =+AT19-AU19 -> -99.419051
A20: =+$A$8 -> Acute_DIV1 | B20: =+$B$8 -> 127 | C20: 91005 | D20: Total IP Adult | E20: =_xll.OneStreamExcelAddIn.XFFunctions.XFGetCell("True","Consol", $B20,"Tot_Entity","USD",E$2,E$3,E$4,$C20,"TopFlow","Top","Top","Tot_Los","TOT_IP_Adult","Tot_FC",$A20,"Top5","Top6","Reported","Top8") -> 113 | F20: =_xll.OneStreamExcelAddIn.XFFunctions.XFGetCell("True","Consol", $B20,"Tot_Entity","Aggregated",F$2,F$3,F$4,$C20,"TopFlow","Top","Top","Tot_Los","TOT_IP_Adult","TOP3",$A20,"Top5","Top6","Reported","Top8") -> 143.98437 | G20: =+E20-F20 -> -30.984374 | M20: =_xll.OneStreamExcelAddIn.XFFunctions.XFGetCell("True","Consol", $B20,"Tot_Entity","USD",M$2,M$3,M$4,$C20,"TopFlow","Top","Top","Tot_Los","TOT_IP_Adult","Tot_FC",$A20,"Top5","Top6","Reported","Top8") -> 113 | N20: =_xll.OneStreamExcelAddIn.XFFunctions.XFGetCell("True","Consol", $B20,"Tot_Entity","USD",N$2,N$3,N$4,$C20,"TopFlow","Top","Top","Tot_Los","TOT_IP_Adult","Tot_FC",$A20,"Top5","Top6","Reported","Top8") -> 119 | O20: =+M20-N20 -> -6 | V20: =_xll.OneStreamExcelAddIn.XFFunctions.XFGetCell("True","Consol", $B20,"Tot_Entity","USD",V$2,V$3,V$4,$C20,"TopFlow","Top","Top","Tot_Los","TOT_IP_Adult","Tot_FC",$A20,"Top5","Top6","Reported","Top8") -> 471 | W20: =_xll.OneStreamExcelAddIn.XFFunctions.XFGetCell("True","Consol", $B20,"Tot_Entity","Aggregated",W$2,W$3,W$4,$C20,"TopFlow","Top","Top","Tot_Los","TOT_IP_Adult","TOP3",$A20,"Top5","Top6","Reported","Top8") -> 594.97572 | X20: =+V20-W20 -> -123.97572 | AD20: =_xll.OneStreamExcelAddIn.XFFunctions.XFGetCell("True","Consol", $B20,"Tot_Entity","USD",AD$2,AD$3,AD$4,$C20,"TopFlow","Top","Top","Tot_Los","TOT_IP_Adult","Tot_FC",$A20,"Top5","Top6","Reported","Top8") -> 113 | AE20: =_xll.OneStreamExcelAddIn.XFFunctions.XFGetCell("True","Consol", $B20,"Tot_Entity","USD",AE$2,AE$3,AE$4,$C20,"TopFlow","Top","Top","Tot_Los","TOT_IP_Adult","Tot_FC",$A20,"Top5","Top6","Reported","Top8") -> 115 | AF20: =+AD20-AE20 -> -2 | AL20: =_xll.OneStreamExcelAddIn.XFFunctions.XFGetCell("True","Consol", $B20,"Tot_Entity","USD",AL$2,AL$3,AL$4,$C20,"TopFlow","Top","Top","Tot_Los","TOT_IP_Adult","Tot_FC",$A20,"Top5","Top6","Reported","Top8") -> 471 | AM20: =_xll.OneStreamExcelAddIn.XFFunctions.XFGetCell("True","Consol", $B20,"Tot_Entity","USD",AM$2,AM$3,AM$4,$C20,"TopFlow","Top","Top","Tot_Los","TOT_IP_Adult","Tot_FC",$A20,"Top5","Top6","Reported","Top8") -> 471 | AN20: =+AL20-AM20 -> 0 | AT20: =_xll.OneStreamExcelAddIn.XFFunctions.XFGetCell("True","Consol", $B20,"Tot_Entity","USD",AT$2,AT$3,AT$4,$C20,"TopFlow","Top","Top","Tot_Los","TOT_IP_Adult","Tot_FC",$A20,"Top5","Top6","Reported","Top8") -> 0 | AU20: =_xll.OneStreamExcelAddIn.XFFunctions.XFGetCell("True","Consol", $B20,"Tot_Entity","USD",AU$2,AU$3,AU$4,$C20,"TopFlow","Top","Top","Tot_Los","TOT_IP_Adult","Tot_FC",$A20,"Top5","Top6","Reported","Top8") -> 143.98437 | AV20: =+AT20-AU20 -> -143.98437
